Workbook

Sheet Parents contact
B1: Column1 | C1: Column2 | D1: Column3 | E1: Column4 | F1: Column5 | G1: Column6 | H1: Column8 | I1: Column9
A2: Tomi | B2: tomi@hif.vn | C2: 0777312249 | D2: Explorers
A3: Luke Denness | B3: 11denness@gmail.com | C3: 0878348423 | D3: Explorers
A4: Vu Tran | B4: vunashley@gmail.com | C4: 0867 785 880 | D4: Explorers
A5: Rahel Wuger | B5: rahelwu@psmail.com | D5: Explorers
A6: April Potot | B6: april.potot@gmail.com | C6: 0769 143 379 | D6: Explorers
A7: Mhatet Villezon | B7: mhatet_conqueror@yahoo.com.ph | C7: 0703 244 160 | D7: Explorers
A8: Florence Ogola | B8: kanyidoto@yahoo.com | C8: 0387972867 | D8: Explorers
A9: Irina Kravchenko | B9: irina941213@gmail.com | C9: 0392 893 650
A10: Tim Middleton | B10: beingtimothy@gmail.com | C10: 766013733 | D10: Explorers
A11: Bukola Oke | B11: kebukolah@gmail.com | C11: 355687312 | D11: Explorers
A12: Johanna Manisto | B12: mailboxjohanna@gmail.com | C12: 46709771103 | D12: Explorers
A13: Hien | B13: hoanghiembm@gmail.com | C13: 374327959 | D13: Explorers
A14: Kasey Brubaker | B14: kaseyjo10@gmail.com | C14: 0869 960 625 | D14: Explorers
A15: Isaiah Grey | B15: isaiahgrey@gmail.com | C15: 0208 5976 466 | D15: Explorers
A16: Giselle Henrique | B16: henrique_giselle@yahoo.com.br | C16: 0867 440 712 | D16: Explorers
A17: Eunique De armas | B17: princesseunique31@gmail.com | C17: 0363 097 357 | D17: Explorers
A18: Lena Zheng | B18: lena.zt03@gmail.com | C18: 0772 600 549 | D18: Explorers
A19: Irina Kravchenko | B19: irina941213@gmail.com | C19: 0392 893 650 | D19: Explorers
A20: Hillyer Smith | B20: leadleyconsulting@gmail.com | C20: 0395 190 237 | D20: Explorers
A21: Philip Zarres | B21: philip.m.zarres@gmail.com | C21: +66 83 886 5038 | D21: Explorers
A22: Jonathan McDaniel | B22: jon.mcdaniel@concordiahanoi.org | C22: 0334 202 882 | D22: Explorers
A23: Luke Denness | B23: lldenness@gmail.com | C23: 0878348423 | D23: Explorers
A24: Zina Kim | B24: zinainjx@gmail.com | C24: 0335 459 704 | D24: Explorers
A25: Veronica Custodio | B25: vheroncustodio@gmail.com | C25: 0383 635 185 | D25: Explorers
... A35: Vũ Dũng | B35: myanhclinic@gmail.com | C35: 0842 921 348 | D35: Voyagers
A36: Christine Tumwine | B36: christinetumwine@gmail.com | C36: 0333 298 495
A37: Tam | B37: tamkt0903@gmail.com | C37: 0947 127 544 | D37: Voyagers
A38: Luke Denness | B38: 11denness@gmail.com | C38: 043 534 1916 | D38: Voyagers
A39: Tanya Tiemeyer | B39: tanya.tiemeyer@gmail.com | C39: 0969517482 | D39: Voyagers
A40: Tanya Tiemeyer | B40: tanya.tiemeyer@gmail.com | C40: 0969517482 | D40: Voyagers
A41: Marife Loyola | B41: mafeployola79@gmail.com | C41: 0988 746 619 | D41: Voyagers
A42: Abasiama Daniel | B42: johnsonabasiama170@gmail.com | C42: 0393 290 120 | D42: Voyagers
A43: Tan Lee | B43: letan711@gmail.com | C43: 097 408 80 73 | D43: Voyagers
A44: Thuong Pham | B44: thuongpham20152018@gmail.com | C44: 0389 905 704 | D44: Voyagers
A45: Vần Giàng | B45: hoanghienbm@gmail.com | C45: 091 395 71 73 | D45: Voyagers
A46: Joseph Pham | B46: joseph.pnc@gmail.com | C46: 0984 317 851 | D46: Voyagers
A47: Huy Le | B47: huyln.bk@gmail.com | C47: 0989 901 988 | D47: Voyagers
A48: Jayrbe Apilan | B48: jayrbe_apilan@yahoo.com | C48: 0866 843 273 | D48: Voyagers
... A69: Thang Nguyen | B69: thangnv77@gmail.com | C69: 0904 881 877 | D69: Voyagers
...

Sheet Explorers
A1: Explorers 3 - 4 Years Old
A2: No | B2: First Name | C2: Last Name | D2: Gender | E2: Primary Contact Name | F2: Email | G2: Contact # | H2: Location | I2: 45844 | J2: =I2+7 -> 45851 | K2: =J2+7 -> 45858 | L2: =K2+7 -> 45865 | M2: 45872 | N2: 45886 | O2: 45893 | P2: 45900 | Q2: 45907 | R2: 45914 | S2: 45921 | T2: 45928 | U2: 45935 | V2: 45942 | W2: 45949 | X2: 45956 | Y2: 45963 | Z2: 45970 | AA2: 45977 | AB2: 45984 | AC2: 45991 | AD2: 7-Dce | AE2: 46005 | AF2: 46012 | AG2: 46019 | AH2: 46033 | AI2: 46040 | AJ2: 46047 | AK2: 46054 | AL2: 46061 | AM2: 46068 | AN2: 46075 | AO2: 46082 | AP2: 46089 | AQ2: 46096 | AR2: 46103 | AS2: 46110 | AT2: =AS2+7 -> 46117 | AU2: =AT2+7 -> 46124 | AV2: =AU2+7 -> 46131 | AW2: =AV2+7 -> 46138 | AX2: 46145 | AY2: 46152 | AZ2: 46159 | BA2: 46166 | BB2: 46173 | BC2: 46180 | BD2: 46187 | BE2: =BD2+7 -> 46194 | BF2: =BE2+7 -> 46201 | BG2: =BF2+7 -> 46208 | BH2: =BG2+7 -> 46215 | BI2: =BH2+7 -> 46222 | BJ2: =BI2+7 -> 46229
A3: 1 | B3: Akin | C3: Ogunbawo | D3: Male | E3: Tomi | F3: tomi@hif.vn | G3: 0777312249 | H3: Explorers | I3: yes | J3: yes | L3: yes | N3: yes | O3: yes | P3: yes | Q3: yes | V3: yes | W3: yes | Y3: yes | Z3: yes | AB3: yes | AC3: yes | AF3: yes | AH3: yes | AJ3: yes | AK3: yes | AM3: yes | AN3: yes | AP3: yes | AQ3: yes | AR3: yes | AT3: YES | AU3: YES | AV3: YES | AW3: YES | AX3: YES | AZ3: YES | BD3: YES | BE3: YES | BF3: YES
A4: =A3+1 -> 2 | B4: Clara | C4: Denness | D4: Female | E4: Luke Denness | F4: 11denness@gmail.com | G4: 0878348423 | H4: Explorers | L4: yes | N4: yes | O4: yes | S4: yes | U4: yes | AB4: yes | AH4: yes | AQ4: yes | AV4: YES | AW4: YES | AZ4: YES | BB4: YES | BC4: YES | BD4: YES | BE4: YES | BF4: YES | BG4: YES | BH4: YES
A5: =A4+1 -> 3 | B5: Isaiah | C5: Tran | D5: Male | E5: Vu Tran | F5: vunashley@gmail.com | G5: 0867 785 880 | H5: Explorers | I5: yes | N5: yes | P5: yes | Q5: yes | T5: yes | U5: yes | W5: yes | Y5: yes | Z5: yes | AB5: yes | AD5: yes | AE5: yes | AF5: yes | AH5: yes | AI5: yes | AJ5: yes | AK5: yes | AM5: yes | AN5: yes | AO5: yes | AP5: yes | AQ5: yes | AT5: YES | AU5: YES | AV5: YES | AW5: YES | AX5: YES
A6: =A5+1 -> 4 | B6: Salome | C6: Wuger | D6: Female | E6: Rahel Wuger | F6: rahelwu@psmail.com | H6: Explorers | I6: yes | N6: yes | V6: yes | AB6: yes | AH6: yes | AJ6: yes | AL6: yes | AM6: yes | AV6: YES | AX6: YES | AZ6: YES | BE6: YES
A7: =A6+1 -> 5 | B7: Zekiah | C7: Potot | D7: Male | E7: April Potot | F7: april.potot@gmail.com | G7: 0769 143 379 | H7: Explorers | I7: yes | N7: yes | S7: yes | T7: yes | V7: yes | W7: yes | Y7: yes | AB7: yes | AD7: yes | AF7: yes | AI7: yes | AO7: yes | AP7: yes | AQ7: yes | AV7: YES | AW7: YES | BA7: YES
A8: =A7+1 -> 6 | B8: Zak | C8: Villezon | D8: Male | E8: Mhatet Villezon | F8: mhatet_conqueror@yahoo.com.ph | G8: 0703 244 160 | H8: Explorers | L8: yes | N8: yes | P8: yes | Q8: yes | U8: yes | V8: yes | W8: yes | Y8: yes | AB8: yes | AM8: yes | AN8: yes | AO8: yes | AQ8: yes | BB8: YES | BF8: YES | BG8: YES | BI8: YES
A9: =A8+1 -> 7 | B9: Ephrain | C9: Ogola | D9: Male | E9: Florence Ogola | F9: kanyidoto@yahoo.com | G9: 0387972867 | H9: Explorers | N9: yes | O9: yes | S9: yes | T9: yes | U9: yes | V9: yes | Z9: yes | AB9: yes | AC9: yes | AI9: yes | AJ9: yes | AK9: yes | AL9: yes | AN9: yes | AO9: yes | AR9: yes | AT9: YES | AU9: YES | AV9: YES | AW9: YES | AX9: YES | AZ9: YES | BB9: YES | BC9: YES | BD9: YES | BE9: YES
A10: =A9+1 -> 8 | B10: Elie | C10: Cha | D10: Female | E10: Irina Kravchenko | F10: irina941213@gmail.com | G10: 0392 893 650 | H10: Explorers | O10: yes | P10: yes | S10: yes | T10: yes | U10: yes | W10: yes | Z10: yes | AD10: yes | AI10: yes | AJ10: yes | AK10: yes | AP10: yes | AQ10: yes | AT10: YES | AV10: YES | AW10: YES | AX10: YES | BB10: YES
A11: =A10+1 -> 9 | B11: Keli | C11: Middleton | D11: Female | E11: Tim Middleton | F11: beingtimothy@gmail.com | G11: 766013733 | H11: Explorers | O11: yes | P11: yes | Q11: yes | U11: yes | Z11: yes | AI11: yes | AO11: yes | AV11: YES | AZ11: YES | BA11: YES | BD11: YES | BH11: YES
A12: =A11+1 -> 10 | B12: Petra | C12: Udoh | D12: Female | E12: Bukola Oke | F12: kebukolah@gmail.com | G12: 355687312 | H12: Explorers | O12: yes | Q12: yes | T12: yes | V12: yes | W12: yes | Y12: yes | AB12: yes | AD12: yes | AK12: yes | AP12: yes | AW12: YES | BD12: YES | BF12: YES | BG12: YES | BI12: YES
A13: =A12+1 -> 11 | B13: Emmi | C13: Manisto | D13: Female | E13: Johanna Manisto | F13: mailboxjohanna@gmail.com | G13: 46709771103 | H13: Explorers | O13: yes
A14: =A13+1 -> 12 | B14: Thien An | C14: Giang | D14: Male | E14: Hien | F14: hoanghiembm@gmail.com | G14: 374327959 | H14: Explorers | O14: yes
A15: =A14+1 -> 13 | B15: Micah | C15: Brubaker | D15: Male | E15: Kasey Brubaker | F15: kaseyjo10@gmail.com | G15: 0869 960 625 | H15: Explorers | P15: yes | S15: yes | U15: yes | X15: yes | AQ15: yes
A16: =A15+1 -> 14 | B16: Noah | C16: Grey | D16: Male | E16: Isaiah Grey | F16: isaiahgrey@gmail.com | G16: 0208 5976 466 | H16: Explorers | Q16: yes | W16: yes | Z16: yes | AB16: yes | AT16: YES
A17: =A16+1 -> 15 | B17: Athos | C17: Machado | D17: Male | E17: Giselle Henrique | F17: henrique_giselle@yahoo.com.br | G17: 0867 440 712 | H17: Explorers | Q17: yes | T17: yes | U17: yes | X17: yes | Z17: yes | AD17: yes | AF17: yes | AJ17: yes | AK17: yes | AM17: yes | AV17: YES | AX17: YES
A18: =A17+1 -> 16 | B18: Skye | C18: de Armas | D18: Female | E18: Eunique De armas | F18: princesseunique31@gmail.com | G18: 0363 097 357 | H18: Explorers | Q18: yes | S18: yes | V18: yes | AB18: yes | AQ18: yes | BF18: YES | BG18: YES
A19: =A18+1 -> 17 | B19: Noah | C19: Zheng | D19: Male | E19: Lena Zheng | F19: lena.zt03@gmail.com | G19: 0772 600 549 | H19: Explorers | Q19: yes | S19: yes | X19: yes
A20: =A19+1 -> 18 | B20: Leo | C20: Cha | D20: Male | E20: Irina Kravchenko | F20: irina941213@gmail.com | G20: 0392 893 650 | H20: Explorers | S20: yes | T20: yes | U20: yes | AD20: yes | AI20: yes | AJ20: yes | AK20: yes | AO20: yes | AT20: YES | AV20: YES | AW20: YES | AX20: YES | BA20: YES | BB20: YES
A21: =A20+1 -> 19 | B21: Cornielle | C21: Smith | D21: Female | E21: Hillyer Smith | F21: leadleyconsulting@gmail.com | G21: 0395 190 237 | H21: Explorers | S21: yes | AQ21: yes
A22: =A21+1 -> 20 | B22: Emily | C22: Zarres | D22: Female | E22: Philip Zarres | F22: philip.m.zarres@gmail.com | G22: +66 83 886 5038 | H22: Explorers | S22: yes | AQ22: yes
A23: =A22+1 -> 21 | B23: Elijah | C23: McDaniel | D23: Male | E23: Jonathan McDaniel | F23: jon.mcdaniel@concordiahanoi.org | G23: 0334 202 882 | H23: Explorers | T23: yes | W23: yes | AO23: yes | AQ23: yes | AV23: YES | AW23: YES | AZ23: YES | BA23: YES
A24: =A23+1 -> 22 | B24: Hanju | C24: Lee | D24: Female | E24: Zina Kim | F24: zinainjx@gmail.com | G24: 0335 459 704 | H24: Explorers | I24: =COUNTIF(I3:I19,"yes") -> 4 | J24: =COUNTIF(J3:J19,"yes") -> 1 | K24: =COUNTIF(K3:K19,"yes") -> 0 | L24: =COUNTIF(L3:L19,"yes") -> 3 | M24: =COUNTIF(M3:M19,"yes") -> 0 | N24: =COUNTIF(N3:N19,"yes") -> 7 | O24: =COUNTIF(O3:O19,"yes") -> 8 | P24: =COUNTIF(P3:P19,"yes") -> 6 | Q24: =COUNTIF(Q3:Q22,"yes") -> 9 | S24: =COUNTIF(S3:S22,"yes") -> 10 | T24: =COUNTIF(T3:T23,"yes") -> 8 | U24: yes | W24: yes | X24: yes | Y24: yes | Z24: yes | AB24: yes | AH24: yes | AI24: yes | AK24: yes | AO24: yes | AR24: yes | AV24: YES | AZ24: YES | BA24: YES | BC24: YES
A25: =A24+1 -> 23 | B25: Noah | C25: Custodio | D25: Male | E25: Veronica Custodio | F25: vheroncustodio@gmail.com | G25: 0383 635 185 | H25: Explorers | Z25: yes | AB25: yes | AH25: yes | AM25: yes | BC25: YES | BH25: YES | BI25: YES
A26: =A25+1 -> 24 | B26: Olivia | C26: Hardegree | D26: Female | E26: Tiffany Hardegree | F26: tmhardegree@gmail.com | G26: 0346051730 | H26: Explorers | W26: yes | X26: yes | AT26: YES | BF26: YES
A27: =A26+1 -> 25 | B27: Faith | C27: Brannon | D27: Female | E27: Grace Brannon | F27: grace.brannon@gmail.com | G27: 0358862482 | H27: Explorers | X27: yes | Y27: yes | AB27: yes | AO27: yes | AQ27: yes
A28: =A27+1 -> 26 | B28: Joanna | C28: Brannon | D28: Female | E28: Grace Brannon | F28: grace.brannon@gmail.com | G28: 0358862482 | H28: Explorers | X28: yes | Y28: yes | AB28: yes | AO28: yes | AQ28: yes
A29: =A28+1 -> 27 | B29: Olivia | C29: Udombat | D29: Female | E29: Inyene Udombat | F29: inyeneudombat@gmail.com | G29: 0364 473 250 | H29: Explorers | X29: yes | Z29: yes | AI29: yes | AJ29: yes | AK29: yes | AM29: yes | AO29: yes | AV29: YES
A30: =A29+1 -> 28 | B30: Ziona | C30: Genelyn | D30: Female | E30: Nickson Thambusamy | F30: tnickson111@gmail.com | G30: 0354 926 814 | H30: Explorers | AD30: yes | AH30: yes | AJ30: yes | AK30: yes | AO30: yes | AR30: yes | AT30: YES | AW30: YES | AX30: YES | AZ30: YES | BA30: YES | BC30: YES
A31: =A30+1 -> 29 | B31: Sutter | H31: Explorers | AI31: yes | AK31: yes
A32: =A31+1 -> 30 | B32: Kyuone | C32: Rhim | D32: Male | E32: Sung Chang Rhim | F32: scrhim.kdbc@gmail.com | G32: 0814 561 598 | H32: Explorers | AI32: yes | AK32: yes
A33: =A32+1 -> 31 | B33: Kyuha | C33: Rhim | D33: Female | E33: Sung Chang Rhim | F33: scrhim.kdbc@gmail.com | G33: 0814 561 598 | H33: Explorers | AI33: yes
A34: =A33+1 -> 32 | B34: Ann | C34: Vu | D34: Female | E34: Stara Nie | F34: niexin19861224@gmail.com | G34: 0967 658 787 | H34: Explorers | AW34: YES | AX34: YES | AZ34: YES
A35: =A34+1 -> 33 | B35: Percy | C35: Keokemoer | D35: Male | E35: Melissa Koekemoer | F35: melissakmr@icloud.com | G35: 0941 296 098 | H35: Explorers | AQ35: yes | AT35: YES | AU35: YES | AV35: YES | BD35: YES | BG35: YES
A36: =A35+1 -> 34 | B36: Samira | H36: Explorers
A37: =A36+1 -> 35 | B37: Lisah | H37: Explorers | AT37: YES | AU37: YES | AV37: YES
A38: =A37+1 -> 36 | B38: Elijah | C38: Middleton | D38: Male | E38: Tim Middleton | F38: beingtimothy@gmail.com | G38: 766013733 | H38: Explorers | AV38: YES | AZ38: YES | BD38: YES
A39: =A38+1 -> 37 | B39: Moon Vy | H39: Explorers | AW39: YES
A40: =A39+1 -> 38 | B40: Jana | C40: Esparar | D40: Female | E40: Jamil Esparar | F40: jamilesparar29@gmail.com | G40: 0344 143 893 | H40: Explorers | AX40: YES | AZ40: YES
...

Sheet Voyagers
A1: Voyagers 5-6 YEARS OLD
A2: No | B2: First Name | C2: Last Name | D2: Gender | E2: Primary Contact Name | F2: Email | G2: Contact # | H2: Location | I2: 45844 | J2: =I2+7 -> 45851 | K2: =J2+7 -> 45858 | L2: =K2+7 -> 45865 | M2: 45872 | N2: 45886 | O2: 45893 | P2: 45900 | Q2: 45907 | R2: 45914 | S2: 45921 | T2: 45928 | U2: 45935 | V2: 45942 | W2: 45949 | X2: 45956 | Y2: 45963 | Z2: 45970 | AA2: 45977 | AB2: 45984 | AC2: 45991 | AD2: 45998 | AE2: 46005 | AF2: 46012 | AG2: 46019 | AH2: 46033 | AI2: 46040 | AJ2: 46047 | AK2: 46054 | AL2: 46061 | AM2: 46068 | AN2: 46075 | AO2: 46082 | AP2: 46089 | AQ2: 46096 | AR2: 46103 | AS2: 46110 | AT2: =AS2+7 -> 46117 | AU2: =AT2+7 -> 46124 | AV2: =AU2+7 -> 46131 | AW2: =AV2+7 -> 46138 | AX2: 46145 | AY2: 46152 | AZ2: 46159 | BA2: 46166 | BB2: 46173 | BC2: 46180 | BD2: 46187 | BE2: =BD2+7 -> 46194 | BF2: =BE2+7 -> 46201 | BG2: =BF2+7 -> 46208 | BH2: =BG2+7 -> 46215 | BI2: =BH2+7 -> 46222 | BJ2: =BI2+7 -> 46229
A3: 1 | B3: Josiah | C3: Tran | D3: Male | E3: Vu Tran | F3: vunashley@gmail.com | G3: 0867 785 880 | H3: Voyagers | I3: yes | J3: yes | K3: yes | N3: yes | P3: yes | Q3: yes | S3: yes | U3: yes | W3: yes | X3: yes | Y3: yes | Z3: yes | AA3: yes | AE3: yes | AF3: yes | AH3: yes | AJ3: yes | AK3: yes | AM3: yes | AN3: yes | AO3: yes | AP3: yes | AQ3: yes | AT3: YES | AU3: YES | AV3: YES | AW3: YES | AX3: YES | BI3: YES
A4: =A3+1 -> 2 | B4: Matthew | C4: Vu Duy | D4: Male | E4: Vũ Dũng | F4: myanhclinic@gmail.com | G4: 0842 921 348 | H4: Voyagers | I4: yes | J4: yes | K4: yes | L4: yes | N4: yes | Q4: yes | S4: yes | T4: yes | V4: yes | W4: yes | Y4: yes | AA4: yes | AC4: yes | AD4: yes | AE4: yes | AF4: yes | AH4: yes | AI4: yes | AK4: yes | AL4: yes | AM4: yes | AN4: yes | AO4: yes | AP4: yes | AQ4: yes | AR4: yes | AT4: YES | AU4: YES | AV4: YES | AW4: YES | AX4: YES | AZ4: YES | BA4: YES | BE4: YES | BG4: YES | BH4: YES | BI4: YES
A5: =A4+1 -> 3 | B5: Alma | C5: Tumwine | D5: Male | E5: Christine Tumwine | F5: christinetumwine@gmail.com | G5: 0333 298 495 | H5: Voyagers | I5: yes | J5: yes | L5: yes | N5: yes | P5: yes | S5: yes | T5: yes | U5: yes | V5: yes | W5: yes | X5: yes | Z5: yes | AA5: yes | AC5: yes | AD5: yes | AE5: yes | AF5: yes | AH5: yes | AI5: yes | AJ5: yes | AL5: yes | AN5: yes | AO5: yes | AP5: yes | AQ5: yes | AR5: yes | AT5: YES | AU5: YES | AV5: YES | AW5: YES | AX5: YES | AZ5: YES | BA5: YES | BB5: YES | BD5: YES | BE5: YES | BF5: YES | BH5: YES | BI5: YES
A6: =A5+1 -> 4 | B6: Kenny | C6: Nguyen | D6: Male | E6: Tam | F6: tamkt0903@gmail.com | G6: 0947 127 544 | H6: Voyagers | L6: yes | N6: yes | O6: yes | Q6: yes | W6: yes
A7: =A6+1 -> 5 | B7: Alyssa | C7: Denness | D7: Female | E7: Luke Denness | F7: 11denness@gmail.com | G7: 043 534 1916 | H7: Voyagers | L7: yes | N7: yes | U7: yes | AA7: yes | AE7: yes | AT7: YES | AV7: YES | AW7: YES | AZ7: YES | BB7: YES | BC7: YES | BD7: YES | BE7: YES | BF7: YES | BG7: YES | BH7: YES
A8: =A7+1 -> 6 | B8: Solomon | C8: Tiemeyer | D8: Male | E8: Tanya Tiemeyer | F8: tanya.tiemeyer@gmail.com | G8: 0969517482 | H8: Voyagers | N8: yes | P8: yes | Q8: yes
A9: =A8+1 -> 7 | B9: Anastasia | C9: Tiemeyer | D9: Female | E9: Tanya Tiemeyer | F9: tanya.tiemeyer@gmail.com | G9: 0969517482 | H9: Voyagers | N9: yes | Q9: yes | S9: yes
A10: =A9+1 -> 8 | B10: Jaja | C10: Loyola | D10: Female | E10: Marife Loyola | F10: mafeployola79@gmail.com | G10: 0988 746 619 | H10: Voyagers | L10: yes | N10: yes | O10: yes | P10: yes | Q10: yes | T10: yes | U10: yes | V10: yes | W10: yes | X10: yes | Y10: yes | Z10: yes | AA10: yes | AC10: yes | AD10: yes | AE10: yes | AF10: yes | AH10: yes | AI10: yes | AJ10: yes | AK10: yes | AL10: yes | AM10: yes | AN10: yes | AO10: yes | AP10: yes | AQ10: yes | AR10: yes | AT10: YES | AU10: YES | AW10: YES | AX10: YES | AZ10: YES | BI10: YES
A11: =A10+1 -> 9 | B11: Cherry | C11: Lee | D11: Female | E11: Tan Lee | F11: letan711@gmail.com | G11: 097 408 80 73 | H11: Voyagers | O11: yes | Q11: yes | T11: yes | V11: yes | W11: yes | X11: yes | Y11: yes | Z11: yes | AA11: yes | AD11: yes | AE11: yes | AF11: yes | AH11: yes | AI11: yes | AK11: yes | AL11: yes | AO11: yes | AP11: yes | AR11: yes | AZ11: YES | BA11: YES | BC11: YES | BD11: YES | BE11: YES | BF11: YES | BG11: YES | BH11: YES | BI11: YES
A12: =A11+1 -> 10 | B12: Leo | C12: Le | D12: Male | E12: Thuong Pham | F12: thuongpham20152018@gmail.com | G12: 0389 905 704 | H12: Voyagers | O12: yes | V12: yes | AI12: yes | AU12: YES
A13: =A12+1 -> 11 | B13: Thiện Nhân | C13: Giàng | D13: Male | E13: Vần Giàng | F13: hoanghienbm@gmail.com | G13: 091 395 71 73 | H13: Voyagers | O13: yes
A14: =A13+1 -> 12 | B14: Gabriel | C14: Pham | D14: Male | E14: Joseph Pham | F14: joseph.pnc@gmail.com | G14: 0984 317 851 | H14: Voyagers | O14: yes
A15: =A14+1 -> 13 | B15: Minh | C15: Le | D15: Female | E15: Huy Le | F15: huyln.bk@gmail.com | G15: 0989 901 988 | H15: Voyagers | O15: yes
A16: =A15+1 -> 14 | B16: Elianna | C16: Apilan | D16: Female | E16: Jayrbe Apilan | F16: jayrbe_apilan@yahoo.com | G16: 0866 843 273 | H16: Voyagers | I16: yes | J16: yes | L16: yes | P16: yes | S16: yes | T16: yes | U16: yes | V16: yes | W16: yes | X16: yes | Y16: yes | AA16: yes | AC16: yes | AD16: yes | AE16: yes | AF16: yes | AI16: yes | AJ16: yes | AK16: yes | AN16: yes | AO16: yes | AP16: yes | AQ16: yes | AR16: yes | AT16: YES | AU16: YES | AW16: YES | AX16: YES | BA16: YES
A17: =A16+1 -> 15 | B17: Chanyoung (Chan) | C17: Park | D17: Male | E17: Lihong Park | F17: eera.park@gmail.com | G17: 0823 416 299 | H17: Voyagers | O17: yes | P17: yes | Q17: yes | S17: yes | T17: yes | U17: yes | W17: yes | X17: yes | Y17: yes | AA17: yes | AC17: yes | AD17: yes | AE17: yes | AF17: yes | AH17: yes | AI17: yes | AK17: yes | AL17: yes | AO17: yes | AP17: yes | AQ17: yes | AT17: YES | AU17: YES | AV17: YES | AW17: YES | AZ17: YES | BA17: YES | BB17: YES | BC17: YES
A18: =A17+1 -> 16 | B18: Kayden | C18: Natanael | D18: Male | E18: Alfred Natanael | F18: alfred.christianto@gmail.com | G18: 0346 167 037 | H18: Voyagers | O18: yes | P18: yes | Q18: yes | S18: yes | T18: yes | U18: yes | W18: yes | X18: yes | Y18: yes | AA18: yes | AC18: yes | AD18: yes | AE18: yes | AH18: yes | AI18: yes | AJ18: yes | AK18: yes | AL18: yes | AO18: yes | AP18: yes | AQ18: yes | AR18: yes | AT18: YES | AU18: YES | AV18: YES | AW18: YES | AX18: YES | AZ18: YES | BA18: YES | BC18: YES
A19: =A18+1 -> 17 | B19: Everly | C19: Brubaker | D19: Female | E19: Kasey Brubaker | F19: kaseyjo10@gmail.com | G19: 0869 960 625 | H19: Voyagers | P19: yes | S19: yes | U19: yes | X19: yes | AZ19: YES
A20: =A19+1 -> 18 | B20: Elijah | C20: Middleton | D20: Male | E20: Yvette Middleton | F20: yvette.huisamen@gmail.com | G20: 0793 094 792 | H20: Voyagers | P20: yes | Q20: yes | V20: yes | Y20: yes
A21: =A20+1 -> 19 | B21: Dante | C21: Machado | D21: Male | E21: Giselle Henrique | F21: henrique_giselle@yahoo.com.br | G21: 0867 440 712 | H21: Voyagers | Q21: yes | T21: yes | X21: yes | AD21: yes | AF21: yes | AJ21: yes | AK21: yes | AM21: yes | AQ21: yes | AX21: YES | BB21: YES
A22: =Trailblazers!A42+1 -> 41 | B22: Liam | C22: Worrell | D22: Male | E22: Wayne Worrell | F22: wayne_m_worrell@hotmail.com | G22: 091 961 92 77 | H22: Voyagers | O22: yes | Q22: yes | W22: yes
A23: =A22+1 -> 42 | B23: Abigail | C23: Bui | D23: Female | E23: Hung Bui | F23: hungbui.penn@gmail.com | G23: 0377 612 426 | H23: Voyagers | O23: yes | P23: yes | Q23: yes | AZ23: YES | BB23: YES
A24: =A23+1 -> 43 | B24: Sophia | C24: Jugunta | D24: Female | E24: Vinoth Jugunta | F24: pinkn112@gmail.com | G24: 0916 226 559 | H24: Voyagers | Q24: yes | S24: yes | T24: yes | U24: yes | Y24: yes | AI24: yes | AJ24: yes | AL24: yes | AO24: yes | AP24: yes | AQ24: yes | AR24: yes | AT24: YES | AU24: YES | AW24: YES | AZ24: YES | BA24: YES | BB24: YES
A25: =A24+1 -> 44 | B25: Matthew | C25: Zheng | D25: Male | E25: Lena Zheng | F25: lena.zt03@gmail.com | G25: 0772 600 549 | H25: Voyagers | Q25: yes | S25: yes | U25: yes | W25: yes | X25: yes | Z25: yes | AA25: yes | AC25: yes | AD25: yes | AE25: yes | AI25: yes | AJ25: yes | AP25: yes | AR25: yes
A26: =A25+1 -> 45 | B26: Weston | C26: King | D26: Male | E26: Leslie King | F26: leslie.king@concordiahanoi.org | G26: 0978 945 282 | H26: Voyagers | S26: yes
A27: =A26+1 -> 46 | B27: Mickey | C27: Ngo | D27: Male | E27: Ruby Bui | F27: ruby.bui.vn@gmail.com | G27: 0972 881 598 | H27: Voyagers | S27: yes | T27: yes | Y27: yes | Z27: yes | AD27: yes | AE27: yes | AF27: yes | AI27: yes | AJ27: yes | AL27: yes | AT27: YES | AU27: YES | AV27: YES | AX27: YES | AZ27: YES | BB27: YES
A28: =A27+1 -> 47 | B28: Ella | C28: Blatchley | D28: Female | E28: Elizabeth Blatchley | F28: elizabethblatchley@gmail.com | G28: 0369 035 823 | H28: Voyagers | S28: yes | T28: yes | V28: yes | X28: yes | Z28: yes | AA28: yes | AC28: yes | AH28: yes | AK28: yes | AL28: yes | AN28: yes | AP28: yes | AQ28: yes | AR28: yes | AT28: YES | AV28: YES | AW28: YES | AX28: YES | AZ28: YES | BA28: YES | BB28: YES | BC28: YES
A29: =A28+1 -> 48 | B29: Theo | C29: Chae | D29: Male | E29: David Chae | F29: davidchae7@gmail.com | G29: 0869 613 314 | H29: Voyagers | T29: yes | W29: yes | AA29: yes | AC29: yes | AD29: yes
A30: =A29+1 -> 49 | B30: Hyeim | C30: Kim | D30: Female | E30: Hyoungsun Kim | F30: epaphroditus70@gmail.com | G30: 0386 293 411 | H30: Voyagers | T30: yes | U30: yes | X30: yes | Z30: yes | AA30: yes | AC30: yes | AD30: yes | AE30: yes | AF30: yes | AH30: yes | AW30: YES | BA30: YES | BB30: YES | BC30: YES | BD30: YES | BE30: YES | BF30: YES
A31: =A30+1 -> 50 | B31: Yesha | C31: Fausto | D31: Male | E31: Ernalyn Fausto | F31: ernalynfausto@gmail.com | G31: 0902 285 873 | H31: Voyagers | W31: yes | X31: yes | AO31: yes | AR31: yes | AU31: YES | AV31: YES | AX31: YES | AZ31: YES | BA31: YES | BI31: YES
A32: =A31+1 -> 51 | B32: Bảo Anh | C32: Okello | D32: Female | E32: Anh Ngọc Nguyễn | F32: nguyenanhngoc880402@gmail.com | G32: 0377 026 356 | H32: Voyagers | X32: yes | AA32: yes | AU32: YES | AX32: YES | AZ32: YES | BI32: YES
A33: =A32+1 -> 52 | B33: Adam | C33: Adams | D33: Male | E33: Naz Adams | F33: naz.cairncross@gmail.com | G33: 0379 859 456 | H33: Voyagers | X33: yes | AA33: yes | AD33: yes | AE33: yes | AJ33: yes | AL33: yes | AO33: yes | AP33: yes | AQ33: yes | AT33: YES | AV33: YES | BA33: YES | BD33: YES | BF33: YES | BG33: YES | BH33: YES | BI33: YES
A34: =A33+1 -> 53 | B34: Marc | C34: Bersales | D34: Male | E34: Elbern Bersales | F34: elbernbersales@gmail.com | G34: 0902 101 348 | H34: Voyagers | Z34: yes | AH34: yes
A35: =A34+1 -> 54 | B35: Leola Ly | C35: Igbokoyi | D35: Female | E35: Cee Jay | F35: princejay4014@gmail.com | G35: 0966 194 000 | H35: Voyagers | AA35: yes | AE35: yes
A36: =A35+1 -> 55 | B36: Nhi | C36: Nguyen | D36: Female | E36: Thang Nguyen | F36: thangnv77@gmail.com | G36: 0904 881 877 | H36: Voyagers | AA36: yes | AC36: yes | AD36: yes | AI36: yes | AL36: yes | AP36: yes | AT36: YES | AW36: YES | AX36: YES | AZ36: YES | BA36: YES | BB36: YES | BC36: YES | BD36: YES | BF36: YES
A37: =A36+1 -> 56 | B37: Mei Linh | C37: Pham | D37: Female | E37: Terri Pham | F37: 715phamily@gmail.com | G37: 862412095 | H37: Voyagers | AD37: yes | AV37: YES | AW37: YES
A38: =A37+1 -> 57 | B38: Ziv | C38: Viillezon | D38: Female | E38: Mhatet VIllezon | F38: Zivvillezon@gmail.com | G38: 703244160 | H38: Voyagers | AD38: yes | AG38: yes | AI38: yes | AK38: yes | AT38: YES | AU38: YES | AV38: YES | AW38: YES | BF38: YES | BG38: YES | BH38: YES
A39: =A38+1 -> 58 | B39: Yao | H39: Voyagers | AE39: yes
A40: =A39+1 -> 59 | B40: Zoe | H40: Voyagers | AE40: yes | BF40: YES
...

Sheet Trailblazers
A1: Traiblazers 7-8 years old
A2: No | B2: First Name | C2: Last Name | D2: Gender | E2: Primary Contact Name | F2: Email | G2: Contact # | H2: Location | I2: 6-Jul | J2: 13-Jul | K2: 20-Jul | L2: 27-Jul | M2: 3-Aug | N2: 17-Aug | O2: 24-Aug | P2: 31-Aug | Q2: 7-Sep | R2: 14-Sep | S2: 21-Sep | T2: 28-Sep | U2: 5-Oct | V2: 12-Oct | W2: 19-Oct | X2: 26-Oct | Y2: 2-Nov | Z2: 9-Nov | AA2: 16-Nov | AB2: 23-Nov | AC2: 45991 | AD2: 7-Dce | AE2: 46005 | AF2: 46012 | AG2: 46019 | AH2: 46033 | AI2: 46040 | AJ2: 46047 | AK2: 46054 | AL2: 46061 | AM2: 46068 | AN2: 46075 | AO2: 46082 | AP2: 46089 | AQ2: 46096 | AR2: 46103 | AS2: 46110 | AT2: =AS2+7 -> 46117 | AU2: =AT2+7 -> 46124 | AV2: =AU2+7 -> 46131 | AW2: =AV2+7 -> 46138 | AX2: 46145 | AY2: 46152 | AZ2: 46159 | BA2: 46166 | BB2: 46173 | BC2: 46180 | BD2: 46187 | BE2: =BD2+7 -> 46194 | BF2: =BE2+7 -> 46201 | BG2: =BF2+7 -> 46208 | BH2: =BG2+7 -> 46215 | BI2: =BH2+7 -> 46222 | BJ2: =BI2+7 -> 46229
A3: 1 | B3: Anna | C3: Lee | D3: Female | E3: Tan Lee | F3: letan711@gmail.com | G3: 097 408 80 73 | H3: Trailblazers | I3: yes | J3: yes | K3: yes | N3: yes | O3: yes | Q3: yes | S3: yes | V3: yes | W3: yes | X3: yes | Y3: yes | Z3: yes | AA3: yes | AB3: yes | AD3: yes | AE3: yes | AH3: yes | AI3: yes | AJ3: yes | AK3: yes | AL3: yes | AO3: yes | AP3: yes | AR3: yes | AT3: YES | AU3: YES | AV3: YES | AX3: YES | AY3: YES | AZ3: YES | BA3: YES | BC3: YES | BD3: YES | BE3: YES | BF3: YES | BG3: YES | BH3: YES | BI3: YES
A4: =A3+1 -> 2 | B4: Juliet | C4: Trần | D4: Female | E4: Thanh Xuân | F4: tranthanhxuan83tmh@gmail.com | G4: 0936 655 115 | H4: Trailblazers | I4: yes | J4: yes | K4: yes | L4: yes | N4: yes | O4: yes | Q4: yes | S4: yes | T4: yes | U4: yes | W4: yes | X4: yes | AC4: yes | AD4: yes | AI4: yes | AJ4: yes | AK4: yes | AO4: yes | AP4: yes | AQ4: yes | AR4: yes | AT4: YES | AU4: YES | AV4: YES | AW4: YES | AY4: YES | BD4: YES | BH4: YES
A5: =A4+1 -> 3 | B5: Manuela | C5: Wuger | D5: Female | E5: rahelwu@psmail.com | H5: Trailblazers | I5: yes | J5: yes | K5: yes | O5: yes | V5: yes | AA5: yes | AB5: yes | AH5: yes | AL5: yes | AM5: yes | AV5: YES | AX5: YES | AZ5: YES | BE5: YES
A6: =A5+1 -> 4 | B6: Nhat Anh | C6: Cao | D6: Female | E6: Cao Van Lung | F6: caovanlungpeter@gmail.com | G6: 977159246 | H6: Trailblazers | I6: yes | J6: yes | K6: yes | L6: yes | N6: yes | O6: yes | Q6: yes | S6: yes | T6: yes | U6: yes | V6: yes | X6: yes | AB6: yes | AV6: YES
A7: =A6+1 -> 5 | B7: Otto | C7: Machado | D7: Male | E7: Giselle Henrique | F7: henrique_giselle@yahoo.com.br | G7: 0867 440 712 | H7: Trailblazers | K7: yes | N7: yes | O7: yes | Q7: yes | T7: yes | U7: yes | X7: yes | AB7: yes | AD7: yes | AJ7: yes | AK7: yes | AM7: yes | AQ7: yes | AX7: YES
A8: =A7+1 -> 6 | B8: Leo | C8: Le | D8: Male | E8: Thuong Pham | F8: thuongpham20152018@gmail.com | G8: 0389 905 704 | H8: Trailblazers | I8: yes | J8: yes | N8: yes | O8: yes | Q8: yes | S8: yes | T8: yes | U8: yes | V8: yes | W8: yes | Y8: yes | Z8: yes | AB8: yes | AD8: yes | AE8: yes | AI8: yes | AJ8: yes | AK8: yes | AL8: yes | AN8: yes | AO8: yes | AP8: yes | AQ8: yes | AR8: yes | AT8: YES | AU8: YES | AV8: YES | AW8: YES | AY8: YES | AZ8: YES | BA8: YES | BB8: YES | BC8: YES | BD8: YES | BF8: YES | BG8: YES | BI8: YES
A9: =A8+1 -> 7 | B9: Hải Anh | C9: Đặng | D9: Female | E9: Nguyễn Khánh Chi | F9: khanhchi0708@gmail.com | G9: 982077882 | H9: Trailblazers | N9: yes | O9: yes
A10: =A9+1 -> 8 | B10: Weston | C10: King | D10: Male | E10: Leslie King | F10: leslie.king@concordiahanoi.org | G10: 0978 945 282 | H10: Trailblazers | O10: yes
A11: =A10+1 -> 9 | B11: Ella | C11: Blatchley | D11: Female | E11: Elizabeth Blatchley | F11: elizabethblatchley@gmail.com | G11: 0369 035 823 | H11: Trailblazers | O11: yes
A12: =A11+1 -> 10 | B12: Yesha | C12: Fausto | D12: Male | E12: Ernalyn Fausto | F12: ernalynfausto@gmail.com | G12: 0902 285 873 | H12: Trailblazers | O12: yes
A13: =A12+1 -> 11 | B13: Jenny | C13: Yeo | D13: Female | E13: Cholong Baek | F13: 7426408@naver.com | G13: 0325 411 009 | H13: Trailblazers | O13: yes
A14: =A13+1 -> 12 | B14: Margaux | C14: Rufo | D14: Female | E14: Mary Rufo | F14: mmparagas19@gmail.com | G14: 0348 903 602 | H14: Trailblazers | O14: yes | Q14: yes | S14: yes | T14: yes | U14: yes | V14: yes | W14: yes | Z14: yes | AA14: yes | AC14: yes | AD14: yes | AI14: yes | AJ14: yes | AK14: yes | AL14: yes | AO14: yes | AP14: yes | AT14: YES | AV14: YES | AW14: YES | BA14: YES | BC14: YES | BD14: YES | BE14: YES | BF14: YES | BH14: YES | BI14: YES
A15: =A14+1 -> 13 | B15: Asher | C15: Tumwine | D15: Male | E15: Christine Tumwine | F15: christinetumwine@gmail.com | G15: 0333 298 495 | H15: Trailblazers | N15: yes | O15: yes | Q15: yes | S15: yes | T15: yes | U15: yes | V15: yes | W15: yes | X15: yes | Z15: yes | AA15: yes | AB15: yes | AC15: yes | AD15: yes | AE15: yes | AH15: yes | AI15: yes | AJ15: yes | AL15: yes | AN15: yes | AO15: yes | AP15: yes | AR15: yes | AT15: YES | AU15: YES | AV15: YES | AW15: YES | AX15: YES | AY15: YES | AZ15: YES | BA15: YES | BB15: YES | BD15: YES | BE15: YES | BF15: YES | BH15: YES | BI15: YES
A16: =A15+1 -> 14 | B16: Edric (Eggsy) | C16: Jugunta | D16: Male | E16: Vinoth Jugunta | F16: pinkn112@gmail.com | G16: 0916 226 559 | H16: Trailblazers | Q16: yes | S16: yes | T16: yes | U16: yes | X16: yes | Y16: yes | Z16: yes | AB16: yes | AD16: yes | AE16: yes | AJ16: yes | AL16: yes | AO16: yes | AP16: yes | AQ16: yes | AR16: yes | AT16: YES | AV16: YES | AW16: YES | AX16: YES | AY16: YES | AZ16: YES | BA16: YES | BB16: YES
A17: =A16+1 -> 15 | B17: Rosemary (Rosie) | C17: Kletzing | D17: Female | E17: Elizabeth Kletzing | F17: elizabeth.kletzing@gmail.com | G17: 0975 439 321 | H17: Trailblazers | Q17: yes | U17: yes | V17: yes | W17: yes | X17: yes | AB17: yes | AC17: yes | AD17: yes | AH17: yes | AI17: yes | AJ17: yes | AL17: yes | AP17: yes | AQ17: yes | AU17: YES | AV17: YES | AW17: YES | AX17: YES | AY17: YES
A18: =A17+1 -> 16 | B18: Isaac | C18: Bennett | D18: Male | E18: Huong Bennett | F18: huonghd85@gmail.com | G18: 0383 231 380 | H18: Trailblazers | Q18: yes | BF18: YES
A19: =A18+1 -> 17 | B19: Raffa Sofiya | C19: Lega | D19: Female | E19: Jenelle Lega | F19: jillrxs@gmail.com | G19: 0334005247 | H19: Trailblazers | I19: yes | J19: yes | K19: yes | N19: yes | O19: yes | Q19: yes | U19: yes | V19: yes | W19: yes | X19: yes | Y19: yes | AA19: yes | AB19: yes | AD19: yes | AE19: yes | AH19: yes | AI19: yes | AJ19: yes | AK19: yes | AN19: yes | AO19: yes | AP19: yes | AQ19: yes | AR19: yes | AT19: YES | AV19: YES | AW19: YES | AX19: YES | AZ19: YES | BG19: YES | BH19: YES | BI19: YES
A20: =A19+1 -> 18 | B20: Masaaki (Aki) | C20: Yamanokawa | D20: Male | E20: Natsuho Yamanokawa | F20: quantity01701@gmail.com | G20: 0385987672 | H20: Trailblazers | S20: yes | V20: yes | AC20: yes | AD20: yes | AH20: yes | AN20: yes | AO20: yes
A21: =A20+1 -> 19 | B21: Emme | C21: Archer | D21: Female | E21: Marine Archer | F21: marinejordaan@gmail.com | G21: 0886 188 682 | H21: Trailblazers | O21: yes | S21: yes | AN21: yes
A22: =A21+1 -> 20 | B22: Lucas | C22: Chae | D22: Male | E22: David Chae | F22: davidchae7@gmail.com | G22: 0869 613 314 | H22: Trailblazers | S22: yes | T22: yes | AA22: yes | AB22: yes | AC22: yes | AY22: YES
A23: =A22+1 -> 21 | B23: Sveinn | C23: Quinones | D23: Male | E23: Shirley Quinones | F23: quinonesshirley35@gmail.com | G23: 090 220 17 53 | H23: Trailblazers | T23: yes | V23: yes | AB23: yes | AC23: yes | AH23: yes | AL23: yes | AN23: yes | AR23: yes | AU23: YES | AW23: YES | BA23: YES | BB23: YES | BD23: YES | BF23: YES
A24: =A23+1 -> 22 | B24: Larissa | C24: Soares | D24: Female | E24: Veronica Soares | F24: veronicaduarte61@gmail.com | G24: 0813 091 451 | H24: Trailblazers | I24: =COUNTIF(I3:I19,"yes") -> 6 | J24: =COUNTIF(J3:J19,"yes") -> 6 | K24: =COUNTIF(K3:K19,"yes") -> 6 | L24: =COUNTIF(L3:L19,"yes") -> 2 | M24: =COUNTIF(M3:M19,"yes") -> 0 | N24: =COUNTIF(N3:N19,"yes") -> 8 | O24: =COUNTIF(O3:O19,"yes") -> 14 | P24: =COUNTIF(P3:P19,"yes") -> 0 | Q24: =COUNTIF(Q3:Q22,"yes") -> 11 | S24: =COUNTIF(S3:S23,"yes") -> 10 | T24: =COUNTIF(T3:T23,"yes") -> 9 | U24: yes | AT24: YES
A25: =A24+1 -> 23 | B25: Zane | C25: Payad | D25: Male | E25: Jonah Payad | F25: jo.payad@gmail.com | G25: 0349 674 539 | H25: Trailblazers | U25: yes | X25: yes | AA25: yes | AE25: yes | AH25: yes | AJ25: yes | AK25: yes | AU25: YES | AW25: YES
A26: =A25+1 -> 24 | B26: Lydia | C26: Tinker | D26: Female | E26: Philip Tinker | F26: philip.tinker@gmail.com | G26: 0808755276 | H26: Trailblazers | U26: yes | AI26: yes
A27: =A26+1 -> 25 | B27: Zachary | C27: Potot | D27: Male | E27: April Potot | F27: april.potot@gmail.com | G27: 0769 143 379 | H27: Trailblazers | I27: yes | N27: yes | S27: yes | T27: yes | V27: yes | Y27: yes | AA27: yes | AD27: yes | AE27: yes | AH27: yes | AI27: yes | AO27: yes | AP27: yes | AQ27: yes | AV27: YES | AW27: YES | AY27: YES | BA27: YES | BB27: YES
A28: =A27+1 -> 26 | B28: Win | C28: Nguyễn | D28: Male | E28: Ly Nguyễn | F28: lynguyen18.work@gmail.com | G28: 0927 158 460 | H28: Trailblazers | W28: yes | Y28: yes | AC28: yes
A29: 27 | B29: Kenny | C29: Nguyen | D29: Male | E29: Rosa Nguyen | F29: tamkt0903@gmail.com | G29: 0947 127 544 | H29: Trailblazers | X29: yes
A30: 28 | B30: Zoe | C30: Le | D30: Female | E30: Gia Rootman | F30: pdsdancestudio@gmail.com | G30: 0869 303 577 | H30: Trailblazers | X30: yes | AX30: YES
A31: 29 | B31: Daniella | C31: Udombat | D31: Female | E31: Inyene Udombat | F31: inyeneudombat@gmail.com | G31: 0364 473 250 | H31: Trailblazers | X31: yes | Z31: yes | AA31: yes | AC31: yes | AD31: yes | AI31: yes | AJ31: yes | AK31: yes | AN31: yes | AO31: yes | AQ31: yes | AT31: YES | AV31: YES | AX31: YES | BA31: YES | BC31: YES | BF31: YES | BH31: YES
A32: 30 | B32: Gabriel | C32: Pham | D32: Male | E32: Ngoc Cuong Joseph Pham | F32: joseph.pnc@gmail.com | G32: 0984 317 851 | H32: Trailblazers | Y32: yes | AA32: yes | AD32: yes | AK32: yes | AT32: YES | AX32: YES
A33: 31 | B33: Liam | C33: Reyes | D33: Male | E33: Judy Reyes | F33: vkpo.jtorres10@gmail.com | G33: 0353 837 006 | H33: Trailblazers | I33: =COUNTIF(Voyagers!I3:I24,"yes") -> 4 | J33: =COUNTIF(Voyagers!J3:J24,"yes") -> 4 | K33: =COUNTIF(Voyagers!K3:K24,"yes") -> 2 | L33: =COUNTIF(Voyagers!L3:L24,"yes") -> 6 | M33: =COUNTIF(Voyagers!M3:M24,"yes") -> 0 | N33: =COUNTIF(Voyagers!N3:N24,"yes") -> 8 | O33: =COUNTIF(Voyagers!O3:O24,"yes") -> 11 | P33: =COUNTIF(Voyagers!P3:P24,"yes") -> 10 | Q33: =COUNTIF(Voyagers!Q3:Q28,"yes") -> 15 | S33: =COUNTIF(Voyagers!S3:S31,"yes") -> 13 | T33: =COUNTIF(Voyagers!T3:T31,"yes") -> 13 | X33: yes | Y33: yes | AB33: yes | AD33: yes | AE33: yes | AH33: yes | AI33: yes | AJ33: yes | AK33: yes | AL33: yes | AN33: yes | AO33: yes | AP33: yes | AQ33: yes | AU33: YES | AV33: YES | AW33: YES | AZ33: YES | BA33: YES | BB33: YES
A34: =Voyagers!A30+1 -> 50 | B34: Seoju | C34: Lee | D34: Male | E34: Zina Kim | F34: zinainjx@gmail.com | G34: 0335 459 704 | H34: Trailblazers | W34: yes | X34: yes | Y34: yes | Z34: yes | AA34: yes | AB34: yes | AC34: yes | AE34: yes | AH34: yes | AI34: yes | AK34: yes | AO34: yes | AQ34: yes | AV34: YES | AZ34: YES | BA34: YES | BB34: YES | BC34: YES | BI34: YES
A35: =Voyagers!A31+1 -> 51 | B35: Enzo | H35: Trailblazers | X35: yes | Y35: yes | AA35: yes | AD35: yes
A36: 34 | B36: Hạnh Nhân | C36: Nguyễn | D36: Female | E36: Thanh Mai Trần | F36: thanhmai1411@gmail.com | G36: 0905 141 128 | H36: Trailblazers | AK36: yes | AR36: yes
A37: 35 | B37: London | H37: Trailblazers | AN37: yes
A38: 36 | B38: Lydia | H38: Trailblazers | AW38: YES
A39: 37 | B39: Joshua | C39: Patterson | D39: Male | E39: Martin Patterson | F39: martinp1987@live.co.uk | G39: 781 591 6960 | H39: Trailblazers | AX39: YES | AZ39: YES
A40: 38 | B40: Zoe | C40: Geleynse | D40: Female | E40: Alex Geleynse | F40: alexbritgel@gmail.com | G40: 0941 581 323 | H40: Trailblazers | AX40: YES | BF40: YES | BG40: YES
...

Sheet Pathfinders
A1: PATHFINDERS 9-11 YEARS OLD
A3: No | B3: First Name | C3: Last Name | D3: Gender | E3: Primary Contact Name | F3: Email | G3: Contact # | H3: Location | I3: 6-Jul | J3: 13-Jul | K3: 20-Jul | L3: 27-Jul | M3: 3-Aug | N3: 17-Aug | O3: 24-Aug | P3: 31-Aug | Q3: 7-Sep | R3: 14-Sep | S3: 21-Sep | T3: 28-Sep | U3: 5-Oct | V3: 12-Oct | W3: 19-Oct | X3: 26-Oct | Y3: 2-Nov | Z3: 9-Nov | AA3: 16-Nov | AB3: 23-Nov | AC3: 45991 | AD3: 45998 | AE3: 14-Dce | AF3: 46012 | AG3: 46019 | AH3: 46033 | AI3: 46040 | AJ3: 46047 | AK3: 46054 | AL3: 46061 | AM3: 46068 | AN3: 46075 | AO3: 46082 | AP3: 46089 | AQ3: 46096 | AR3: 46103 | AS3: 46110 | AT3: =AS3+7 -> 46117 | AU3: =AT3+7 -> 46124 | AV3: =AU3+7 -> 46131 | AW3: =AV3+7 -> 46138 | AX3: 46145 | AY3: 46152 | AZ3: 46159 | BA3: 46166 | BB3: 46173 | BC3: 46180 | BD3: 46187 | BE3: =BD3+7 -> 46194 | BF3: =BE3+7 -> 46201 | BG3: =BF3+7 -> 46208 | BH3: =BG3+7 -> 46215 | BI3: =BH3+7 -> 46222 | BJ3: =BI3+7 -> 46229
A4: 1 | B4: Alice | C4: Le | D4: Female | E4: Thuong Pham | F4: thuongpham20152018@gmail.com | G4: 0389 905 704 | H4: Pathfinders | I4: yes | J4: yes | N4: yes | Q4: yes | S4: yes | T4: yes | U4: yes | W4: yes | Z4: yes | AB4: yes | AD4: yes | AE4: yes | AF4: yes | AI4: yes | AJ4: yes | AT4: YES | BB4: YES | BC4: YES | BD4: YES
A5: =A4+1 -> 2 | B5: Alvaro | C5: Sirait | D5: Male | E5: Ramon Sirait | F5: ramonsirait76@gmail.com | G5: 0936094778 | H5: Pathfinders | I5: yes | N5: yes | Q5: yes | T5: yes | W5: yes | Y5: yes | Z5: yes | AA5: yes | AB5: yes | AE5: yes | AF5: yes
A6: =A5+1 -> 3 | B6: Amy Mai | C6: Chou | D6: Female | E6: Terry Chou | F6: terry090769@gmail.com | G6: 0915 572 004 | H6: Pathfinders | J6: yes | N6: yes | S6: yes | T6: yes | X6: yes | Y6: yes | AB6: yes | AC6: yes | AD6: yes | AF6: yes | AH6: yes | AI6: yes | AJ6: yes | AK6: yes | AL6: yes | AQ6: yes | AU6: YES | AV6: YES | AW6: YES | BA6: YES | BB6: YES | BC6: YES | BF6: YES | BG6: YES | BH6: YES | BI6: YES
A7: =A6+1 -> 4 | B7: Areli | C7: Stevens | D7: Female | E7: Regina Stevens | F7: ar_stevens@icloud.com | G7: 0348 055 084 | H7: Pathfinders | I7: yes | J7: yes | N7: yes
A8: =A7+1 -> 5 | B8: Kris Vincent Isidore | C8: Macay | D8: Male | E8: Lycah Macay | F8: rglyca2003@gmail.com | G8: 0969 279 373 | H8: Pathfinders | J8: yes | N8: yes | Q8: yes
A9: =A8+1 -> 6 | B9: Prince | C9: Lanaban | D9: Male | E9: Ronnil Lanaban | F9: nhelmer26@gmail.com | G9: 0843 284 5391 | H9: Pathfinders | J9: yes | N9: yes | AC9: yes | AT9: YES | AY9: YES | BB9: YES | BH9: YES
A10: =A9+1 -> 7 | B10: Sarah | C10: Quyen | D10: Female | E10: Pham Van Gioi | F10: phamgioi.nd@gmail.com | G10: 0948 878 282 | H10: Pathfinders | I10: yes | J10: yes | O10: yes | V10: yes | Z10: yes | BJ10: YES
A11: =A10+1 -> 8 | B11: Yekang | C11: Kim | D11: Male | E11: Jeong hyun Kim | F11: kimplus83@gmail.com | G11: 0869 397 411 | H11: Pathfinders | I11: yes | Z11: yes | AA11: yes | AB11: yes | AC11: yes | AE11: yes | AH11: yes | AI11: yes | AJ11: yes | AK11: yes | AL11: yes | AM11: yes | AN11: yes | AO11: yes | AP11: yes | AQ11: yes | AR11: yes | AT11: YES | AU11: YES | AW11: YES | AX11: YES | AY11: YES | AZ11: YES | BA11: YES | BB11: YES
A12: =A11+1 -> 9 | B12: Yonjoo | C12: Kim | D12: Female | E12: Seung Wan Kim | F12: seungwan.kim@gmail.com | G12: 0906 262 095 | H12: Pathfinders | J12: yes | N12: yes | O12: yes | S12: yes | T12: yes | U12: yes | W12: yes | X12: yes | Y12: yes | Z12: yes | AA12: yes
A13: =A12+1 -> 10 | B13: Julia | C13: Trần | D13: Female | E13: Tran Thanh Xuan | F13: tranthanhxuan83tmh@gmail.com | G13: 0936 655 115 | H13: Pathfinders | I13: yes | J13: yes | K13: yes | L13: yes | N13: yes | S13: yes | W13: yes | AJ13: yes | AP13: yes | AQ13: yes | AT13: YES | AW13: YES | AY13: YES
A14: =A13+1 -> 11 | B14: Michelle | C14: Nguyen | D14: Female | E14: Kay Thi Khine | F14: khine86@gmail.com | G14: 0944 552 225 | H14: Pathfinders | L14: yes | N14: yes
A15: =A14+1 -> 12 | B15: Katherine | C15: Nguyen | D15: Female | E15: Kay Thi Khine | F15: khine86@gmail.com | G15: 0944 552 225 | H15: Pathfinders | L15: yes | N15: yes
A16: =A15+1 -> 13 | B16: Isaac | C16: Middleton | D16: Male | E16: Yvette Middle | F16: yvette.huisamen@gmail.com | G16: 0793 094 792 | H16: Pathfinders | I16: yes | J16: yes | K16: yes | L16: yes | N16: yes | O16: yes | P16: yes | Q16: yes | U16: yes | V16: yes | W16: yes | Y16: yes | Z16: yes | AB16: yes | AC16: yes | AE16: yes | AO16: yes | AP16: yes | AT16: YES | AV16: YES | AY16: YES | AZ16: YES | BD16: YES | BH16: YES
A17: =A16+1 -> 14 | B17: Emma | C17: Eso | D17: Female | E17: Oluwabukola Eso | F17: hollamydeella@gmail.com | G17: 0812 995 160 | H17: Pathfinders | J17: yes | K17: yes | L17: yes | N17: yes | AO17: yes
A18: =A17+1 -> 15 | B18: Hayley | C18: Keller | D18: Female | E18: Huyen Le | F18: lethuyhuyen@gmail.com | G18: 0904 576 469 | H18: Pathfinders | O18: yes | P18: yes | Q18: yes | S18: yes | T18: yes | U18: yes | W18: yes | X18: yes | Y18: yes | AA18: yes | AD18: yes | AI18: yes | AJ18: yes | AO18: yes | AU18: YES | AW18: YES | AX18: YES | AZ18: YES | BA18: YES | BB18: YES | BC18: YES | BD18: YES | BE18: YES | BH18: YES
A19: =A18+1 -> 16 | B19: Gaeun | C19: Park | D19: Female | E19: Lihong Park | F19: eera.park@gmail.com | G19: 0823 416 299 | H19: Pathfinders | O19: yes | P19: yes | Q19: yes | S19: yes | T19: yes | U19: yes | W19: yes | X19: yes | Y19: yes | Z19: yes | AA19: yes | AB19: yes | AC19: yes | AD19: yes | AE19: yes | AH19: yes | AI19: yes | AK19: yes | AL19: yes | AO19: yes | AP19: yes | AQ19: yes | AR19: yes | AT19: YES | AU19: YES | AW19: YES | AY19: YES | AZ19: YES | BA19: YES | BB19: YES | BC19: YES | BD19: YES | BJ19: YES
A20: =A19+1 -> 17 | B20: Levi | C20: Thiessen | D20: Male | E20: Jeremy Thiessen | F20: jeremycth@yahoo.ca | G20: 0896 641 793 | H20: Pathfinders | O20: yes | P20: yes | Q20: yes | S20: yes | T20: yes | U20: yes | V20: yes | W20: yes | X20: yes | Y20: yes | Z20: yes | AA20: yes | AB20: yes | AC20: yes | AD20: yes | AE20: yes | AI20: yes | AJ20: yes | AK20: yes | AL20: yes | AM20: yes | AN20: yes | AO20: yes | AP20: yes | AR20: yes | AT20: YES | AU20: YES | AW20: YES | AX20: YES | AY20: YES | AZ20: YES | BA20: YES | BC20: YES | BD20: YES
A21: =A20+1 -> 18 | B21: Samuel (Sami) | C21: Thiessen | D21: Male | E21: Jeremy Thiessen | F21: jeremycth@yahoo.ca | G21: 0896 641 793 | H21: Pathfinders | O21: yes | P21: yes | Q21: yes | S21: yes | T21: yes | U21: yes | V21: yes | W21: yes | X21: yes | Y21: yes | Z21: yes | AA21: yes | AB21: yes | AC21: yes | AD21: yes | AE21: yes | AH21: yes | AI21: yes | AJ21: yes | AK21: yes | AL21: yes | AM21: yes | AN21: yes | AO21: yes | AP21: yes | AQ21: yes | AR21: yes | AT21: YES | AU21: YES | AV21: YES | AW21: YES | AX21: YES | AY21: YES | AZ21: YES | BA21: YES | BC21: YES | BD21: YES
A22: =A21+1 -> 19 | B22: Kaitlyn | C22: Natanael | D22: Female | E22: Alfred Natanael | F22: alfred.christianto@gmail.com | G22: 0346 167 037 | H22: Pathfinders | O22: yes | P22: yes | Q22: yes | S22: yes | T22: yes | U22: yes | V22: yes | W22: yes | X22: yes | Y22: yes | Z22: yes | AA22: yes | AB22: yes | AC22: yes | AD22: yes | AE22: yes | AH22: yes | AI22: yes | AJ22: yes | AK22: yes | AL22: yes | AP22: yes | AQ22: yes | AR22: yes | AT22: YES | AU22: YES | AV22: YES | AW22: YES | AX22: YES | AY22: YES | AZ22: YES | BA22: YES | BB22: YES | BC22: YES | BD22: YES
A23: =A22+1 -> 20 | B23: Alethea | C23: Scandrett | D23: Female | E23: Que Anh Nhu | F23: nhuqueanh@yahoo.com | G23: 0962 606 150 | H23: Pathfinders | O23: yes | P23: yes | Q23: yes | S23: yes | T23: yes | U23: yes | W23: yes | X23: yes | Y23: yes | Z23: yes | AA23: yes | AB23: yes | AC23: yes | AD23: yes | AE23: yes | AH23: yes | AJ23: yes | AK23: yes | AL23: yes | AO23: yes | AQ23: yes | AT23: YES | BA23: YES | BB23: YES | BC23: YES | BD23: YES
A24: =A23+1 -> 21 | B24: Elijah | C24: Scandrett | D24: Male | E24: Que Anh Nhu | F24: nhuqueanh@yahoo.com | G24: 0962 606 150 | H24: Pathfinders | O24: yes | P24: yes | Q24: yes | S24: yes | T24: yes | U24: yes | W24: yes | X24: yes | Y24: yes | Z24: yes | AA24: yes | AB24: yes | AD24: yes | AE24: yes | AF24: yes | AH24: yes | AJ24: yes | AK24: yes | AL24: yes | AO24: yes | AP24: yes | AQ24: yes | AV24: YES | AY24: YES | AZ24: YES | BA24: YES | BB24: YES | BC24: YES | BD24: YES | BI24: YES
A25: =Voyagers!A23+1 -> 43 | B25: Rane | C25: Fausto | D25: Male | E25: Ernalyn Fausto | F25: ernalynfausto@gmail.com | G25: 0902 285 873 | H25: Pathfinders | O25: yes | W25: yes | X25: yes | AM25: yes | AR25: yes | AV25: YES | AX25: YES | AY25: YES | AZ25: YES | BA25: YES | BI25: YES | BJ25: YES
A26: =A25+1 -> 44 | B26: Yujin | C26: Lee | D26: Female | E26: Yaejin Lee | F26: jj78.lee@samsung.com | G26: 0971 163 003 | H26: Pathfinders | O26: yes
A27: =A26+1 -> 45 | B27: Lydia | C27: Lim | D27: Female | E27: Della Yu | F27: dellanev@yahoo.com | H27: Pathfinders | O27: yes | S27: yes | T27: yes | V27: yes | Y27: yes | Z27: yes | AB27: yes | AE27: yes | AO27: yes | AQ27: yes | AV27: YES | AW27: YES | AX27: YES | AY27: YES | AZ27: YES | BA27: YES | BB27: YES | BE27: YES | BG27: YES
A28: =A27+1 -> 46 | B28: Jian | C28: Lee | D28: Female | E28: Kyoungsu Lee | F28: qushin622@gmail.com | G28: 0392 414 600 | H28: Pathfinders | O28: yes | Q28: yes | T28: yes | U28: yes | W28: yes | X28: yes | Y28: yes | Z28: yes | AA28: yes | AB28: yes | AC28: yes | AE28: yes | AF28: yes | AH28: yes | AI28: yes | AJ28: yes | AQ28: yes | AR28: yes | AT28: YES | AW28: YES | AY28: YES | AZ28: YES | BA28: YES | BB28: YES | BC28: YES | BD28: YES | BJ28: YES
A29: =A28+1 -> 47 | B29: Mine | C29: Archer | D29: Female | E29: Marine Archer | F29: marinejordaan@gmail.com | G29: 0886 188 682 | H29: Pathfinders | O29: yes | S29: yes | AI29: yes | AM29: yes | AO29: yes
A30: =A29+1 -> 48 | B30: Charisse | C30: Lee | D30: Female | E30: Jason Lee | F30: asyndeton2@gmail.com | H30: Pathfinders | O30: yes | U30: yes | W30: yes | Y30: yes | AC30: yes | AJ30: yes | AQ30: yes | AU30: YES
A31: =A30+1 -> 49 | B31: Jacob | C31: Vu | D31: Male | E31: Jason Vu | F31: Laura.jasonvu@hotmail.com | G31: 0904 031 143 | H31: Pathfinders | O31: yes | Q31: yes | X31: yes | Y31: yes | AK31: yes | AV31: YES | BF31: YES | BI31: YES
A32: =A31+1 -> 50 | B32: Cora | C32: Kletzing | D32: Female | E32: Elizabeth Kletzing | F32: elizabeth.kletzing@gmail.com | G32: 0975 439 321 | H32: Pathfinders | P32: yes | Q32: yes | S32: yes | T32: yes | U32: yes
A33: =A32+1 -> 51 | B33: Zara | C33: Roberts | D33: Female | E33: Rianna Mohammed-Roberts | F33: r.mohammedroberts@gmail.com | G33: 0762 006 052 | H33: Pathfinders | P33: yes | Q33: yes | X33: yes | AA33: yes | AC33: yes | AD33: yes | AM33: yes | AR33: yes
A34: =A33+1 -> 52 | B34: Nicholas | C34: Roberts | D34: Male | E34: Rianna Mohammed-Roberts | F34: r.mohammedroberts@gmail.com | G34: 0762 006 052 | H34: Pathfinders | P34: yes | X34: yes | AA34: yes | AM34: yes | AR34: yes
A35: =A34+1 -> 53 | B35: Hannah | C35: Antony | D35: Female | H35: Pathfinders | P35: yes
A36: =A35+1 -> 54 | B36: Evan | C36: Eiselstein | D36: Male | E36: Deborah Eiselstein | F36: tazha1976@yahoo.com | G36: 0772 600 549 | H36: Pathfinders | Q36: yes | S36: yes | AK36: yes | AO36: Yes | AU36: YES
A37: =A36+1 -> 55 | B37: Jade | C37: Eiselstein | D37: Female | E37: Deborah Eiselstein | F37: tazha1976@yahoo.com | G37: 0772 600 549 | H37: Pathfinders | Q37: yes | S37: yes | AK37: yes | AO37: yes | AT37: YES | AU37: YES | BG37: YES
A38: =A37+1 -> 56 | B38: Angela | C38: Yoteni | D38: Female | E38: Ariella Yoteni | F38: ariella.yoteni@gmail.com | G38: 0904 685 786 | H38: Pathfinders | I38: yes | N38: yes | O38: yes | Q38: yes | BH38: YES | BI38: YES | BJ38: YES
A39: =A38+1 -> 57 | B39: Hoàng Anh | C39: Trần | D39: Female | E39: Hoàng Lan | F39: mshoanglan@gmail.com | G39: 0943 038 686 | H39: Pathfinders | S39: yes
A40: =A39+1 -> 58 | B40: Hoàng Minh | C40: Trần | D40: Male | E40: Hoàng Lan | F40: mshoanglan@gmail.com | G40: 0943 038 686 | H40: Pathfinders | S40: yes
A41: =A40+1 -> 59 | B41: Caspian | C41: Kugler | D41: Male | E41: Caroline Kugler | F41: cmariekugler@gmail.com | G41: 0969 022 750 | H41: Pathfinders | S41: yes | V41: yes | W41: yes | AC41: yes
...

Sheet Parents-Active
A1: KIDZQUEST PARENTS' MAILING LIST AS OF 31 MARCH 2026
B2: Primary Contact Name | C2: Email
A3: 1 | B3: Kay Thi Khine | C3: khine86@gmail.com
A4: =A3+1 -> 2 | B4: Abasiama Daniel | C4: johnsonabasiama170@gmail.com
A5: =A4+1 -> 3 | B5: Alfred Natanael | C5: alfred.christianto@gmail.com
A6: =A5+1 -> 4 | B6: Anh Ngọc Nguyễn | C6: nguyenanhngoc880402@gmail.com
A7: =A6+1 -> 5 | B7: April Potot | C7: april.potot@gmail.com
A8: =A7+1 -> 6 | B8: Ariella Yoteni | C8: ariella.yoteni@gmail.com
A9: =A8+1 -> 7 | B9: Bukola Oke | C9: kebukolah@gmail.com
A10: =A9+1 -> 8 | B10: Cao Van Lung | C10: caovanlungpeter@gmail.com
A11: =A10+1 -> 9 | B11: Caroline Kugler | C11: cmariekugler@gmail.com
A12: =A11+1 -> 10 | B12: Cee Jay | C12: princejay4014@gmail.com
A13: =A12+1 -> 11 | B13: Cholong Baek | C13: 7426408@naver.com
A14: =A13+1 -> 12 | B14: Christine Tumwine | C14: christinetumwine@gmail.com
A15: =A14+1 -> 13 | B15: David Chae | C15: davidchae7@gmail.com
... A112: =A111+1 -> 110 | B112: Zina Kim | C112: zinainjx@gmail.com

Sheet Active-Path
B1: PATHFINDERS, 9-11 YEARS OLD
B3: First Name | C3: Last Name | D3: Gender | E3: Primary Contact Name | F3: Email | G3: Contact # | H3: Location | I3: 46145 | J3: 46152 | K3: 46159 | L3: 46166 | M3: 46173 | N3: 46180 | O3: 46187 | P3: =O3+7 -> 46194 | Q3: =P3+7 -> 46201 | R3: =Q3+7 -> 46208 | S3: =R3+7 -> 46215 | T3: =S3+7 -> 46222 | U3: =T3+7 -> 46229 | V3: =U3+7 -> 46236 | W3: =V3+7 -> 46243 | ... AD3: =AC3+7 -> 46292
A4: 1 | B4: Alethea | C4: Scandrett | D4: Female | E4: Que Anh Nhu | F4: nhuqueanh@yahoo.com | G4: 0962 606 150 | H4: Pathfinders | L4: YES | M4: YES | N4: YES | O4: YES
A5: =A4+1 -> 2 | B5: Alice | C5: Le | D5: Female | E5: Thuong Pham | F5: thuongpham20152018@gmail.com | G5: 0389 905 704 | H5: Pathfinders | M5: YES | N5: YES | O5: YES
A6: =A5+1 -> 3 | B6: Amy Mai | C6: Chou | D6: Female | E6: Terry Chou | F6: terry090769@gmail.com | G6: 0915 572 004 | H6: Pathfinders | L6: YES | M6: YES | N6: YES | Q6: YES | R6: YES | S6: YES | T6: YES | X6: YES
A7: =A6+1 -> 4 | B7: Angela | C7: Yoteni | D7: Female | E7: Ariella Yoteni | F7: ariella.yoteni@gmail.com | G7: 0904 685 786 | H7: Pathfinders | S7: YES | T7: YES | U7: YES
A8: =A7+1 -> 5 | B8: Ariel | H8: Pathfinders | Q8: YES | R8: YES | S8: YES | T8: YES | U8: YES | V8: YES
A9: =A8+1 -> 6 | B9: Bin | C9: Tran | D9: Male | E9: Hang Nguyen | F9: nguyenhang150787@gmail.com | G9: 0395637467 | H9: Pathfinders | J9: YES | L9: YES | M9: YES | N9: YES | O9: YES | Q9: YES | R9: YES | S9: YES | U9: YES
A10: =A9+1 -> 7 | B10: Blake | C10: Adams | D10: Male | E10: Naz Adams | F10: naz.cairncross@gmail.com | G10: 379859456 | H10: Pathfinders | J10: YES | L10: YES | O10: YES | Q10: YES | R10: YES | S10: YES | T10: YES | U10: YES | V10: YES | Y10: YES | Z10: YES
A11: =A10+1 -> 8 | B11: Caleb | H11: Pathfinders | Q11: YES | R11: YES | S11: YES | T11: YES | U11: YES | V11: YES
A12: =A11+1 -> 9 | B12: Daniella | D12: Female | H12: Pathfinders | AA12: YES
A13: =A12+1 -> 10 | B13: Dash | C13: Stevens | D13: Male | E13: Regina Stevens | F13: ar_stevens@icloud.com | G13: 0348 055 084 | H13: Pathfinders | V13: YES | X13: YES | Y13: YES | Z13: YES | AA13: YES
A14: =A13+1 -> 11 | B14: David | H14: Pathfinders | T14: YES | U14: YES
A15: =A14+1 -> 12 | B15: Eliana | C15: Lee | D15: Female | E15: Jason Lee | F15: asyndeton2@gmail.com | H15: Pathfinders | L15: YES | Q15: YES | X15: YES
A16: =A15+1 -> 13 | B16: Elijah | C16: Scandrett | D16: Male | E16: Que Anh Nhu | F16: nhuqueanh@yahoo.com | H16: Pathfinders | J16: YES | K16: YES | L16: YES | M16: YES | N16: YES | O16: YES | T16: YES | W16: YES | Y16: YES
A17: =A16+1 -> 14 | B17: Emme | C17: Archer | H17: Pathfinders | Y17: YES
A18: =A17+1 -> 15 | B18: Evan | C18: Eiselstein | D18: Male | E18: Dee Eiselstein | H18: Pathfinders | V18: YES | W18: YES | X18: YES | Z18: YES | AA18: YES
A19: =A18+1 -> 16 | B19: Evan | C19: Ramirez | H19: Pathfinders | Y19: YES | Z19: YES | AA19: YES
A20: =A19+1 -> 17 | B20: Ezekiel | H20: Pathfinders | V20: YES | AA20: YES
A21: =A20+1 -> 18 | B21: Gaeun | C21: Park | D21: Female | E21: Lihong Park | F21: eera.park@gmail.com | G21: 0823 416 299 | H21: Pathfinders | J21: YES | K21: YES | L21: YES | M21: YES | N21: YES | O21: YES | U21: YES | V21: YES | W21: YES | X21: YES | Z21: YES | AA21: YES
A22: =A21+1 -> 19 | B22: Hayley | C22: Keller | D22: Female | E22: Huyen Le | F22: lethuyhuyen@gmail.com | G22: 0904 576 469 | H22: Pathfinders | I22: YES | K22: YES | L22: YES | M22: YES | N22: YES | O22: YES | P22: YES | S22: YES | X22: YES | Z22: YES | AA22: YES
A23: =A22+1 -> 20 | B23: Isaac | C23: Middleton | D23: Male | E23: Yvette Middle | F23: yvette.huisamen@gmail.com | G23: 0793 094 792 | H23: Pathfinders | J23: YES | K23: YES | O23: YES | S23: YES | V23: YES | W23: YES | Y23: YES | AA23: YES
A24: =A23+1 -> 21 | B24: Isaki | C24: Ngo | D24: Male | E24: Tayuka Ngo | F24: ttayuka@hotmail.com | G24: 0985 126 736 | H24: Pathfinders | I24: YES
A25: =A24+1 -> 22 | B25: Jacob | C25: Vu | D25: Male | E25: Jason Vu | F25: Laura.jasonvu@hotmail.com | G25: 0904 031 143 | H25: Pathfinders | Q25: YES | T25: YES | Z25: YES | AA25: YES
A26: =A25+1 -> 23 | B26: Jade | C26: Eiselstein | D26: Female | E26: Deborah Eiselstein | F26: tazha1976@yahoo.com | G26: 0772 600 549 | H26: Pathfinders | R26: YES | V26: YES | X26: YES | Z26: YES | AA26: YES
A27: =A26+1 -> 24 | B27: Jian | C27: Lee | D27: Female | E27: Kyoungsu Lee | F27: qushin622@gmail.com | G27: 0392 414 600 | H27: Pathfinders | J27: YES | K27: YES | L27: YES | M27: YES | N27: YES | O27: YES | U27: YES | Z27: YES
A28: =A27+1 -> 25 | B28: Jona | C28: Damaske | D28: Male | E28: Jens Damaske | H28: Pathfinders | P28: YES
A29: =A28+1 -> 26 | B29: Julia | C29: Trần | D29: Female | E29: Tran Thanh Xuan | F29: tranthanhxuan83tmh@gmail.com | G29: 0936 655 115 | H29: Pathfinders | J29: YES
A30: =A29+1 -> 27 | B30: Kaitlyn | C30: Natanael | D30: Female | E30: Alfred Natanael | F30: alfred.christianto@gmail.com | G30: 0346 167 037 | H30: Pathfinders | I30: YES | J30: YES | K30: YES | L30: YES | M30: YES | N30: YES | O30: YES | AA30: YES
A31: =A30+1 -> 28 | B31: Katherine | D31: Female | H31: Pathfinders | AA31: YES
A32: =A31+1 -> 29 | B32: Levi | C32: Thiessen | D32: Male | E32: Jeremy Thiessen | F32: jeremycth@yahoo.ca | G32: 0896 641 793 | H32: Pathfinders | I32: YES | J32: YES | K32: YES | L32: YES | N32: YES | O32: YES | W32: YES | X32: YES | Y32: YES | AA32: YES
A33: =A32+1 -> 30 | B33: Luthando | C33: Leora | Z33: YES | AA33: YES
A34: =A33+1 -> 31 | B34: Lydia | C34: Lim | D34: Female | E34: Della Yu | F34: dellanev@yahoo.com | H34: Pathfinders | I34: YES | J34: YES | K34: YES | L34: YES | M34: YES | P34: YES | R34: YES | X34: YES | Z34: YES | AA34: YES
A35: =A34+1 -> 32 | B35: Mai | H35: Pathfinders | T35: YES | W35: YES | X35: YES
A36: =A35+1 -> 33 | B36: Mari | C36: Symmonds | H36: Pathfinders | Y36: YES
A37: =A36+1 -> 34 | B37: Michelle | D37: Female | H37: Pathfinders | AA37: YES
A38: =A37+1 -> 35 | B38: Mine | C38: Archer | H38: Pathfinders | Y38: YES
A39: =A38+1 -> 36 | B39: Otto | C39: Machado | D39: Male | E39: Giselle Henrique | F39: henrique_giselle@yahoo.com.br | G39: 0867 440 712 | H39: Pathfinders | I39: YES | X39: YES | AA39: YES
A40: =A39+1 -> 37 | B40: Prince | C40: Lanaban | D40: Male | E40: Ronnil Lanaban | F40: nhelmer26@gmail.com | G40: 0843 284 5391 | H40: Pathfinders | J40: YES | M40: YES | S40: YES
A41: =A40+1 -> 38 | B41: Rane | C41: Fausto | D41: Male | E41: Ernalyn Fausto | F41: ernalynfausto@gmail.com | G41: 0902 285 873 | H41: Pathfinders | I41: YES | J41: YES | K41: YES | L41: YES | T41: YES | U41: YES | W41: YES | X41: YES | Y41: YES
...

Sheet Active-Trail
B1: TRAILBLAZERS 7-8 YEARS OLD
B2: First Name | C2: Last Name | D2: Gender | E2: Primary Contact Name | F2: Email | G2: Contact # | H2: Location | I2: 46145 | J2: 46152 | K2: 46159 | L2: 46166 | M2: 46173 | N2: 46180 | O2: 46187 | P2: =O2+7 -> 46194 | Q2: =P2+7 -> 46201 | R2: =Q2+7 -> 46208 | S2: =R2+7 -> 46215 | T2: =S2+7 -> 46222 | U2: =T2+7 -> 46229 | V2: =U2+7 -> 46236 | W2: =V2+7 -> 46243 | ... AD2: =AC2+7 -> 46292
A3: 1 | B3: Anna | C3: Lee | D3: Female | E3: Tan Lee | F3: letan711@gmail.com | G3: 097 408 80 73 | H3: Trailblazers | I3: YES | J3: YES | K3: YES | L3: YES | N3: YES | O3: YES | P3: YES | Q3: YES | R3: YES | S3: YES | T3: YES | U3: YES | V3: YES | W3: YES
A4: =A3+1 -> 2 | B4: Asher | C4: Tumwine | D4: Male | E4: Christine Tumwine | F4: christinetumwine@gmail.com | G4: 0333 298 495 | H4: Trailblazers | I4: YES | J4: YES | K4: YES | L4: YES | M4: YES | O4: YES | P4: YES | Q4: YES | S4: YES | T4: YES | U4: YES | V4: YES | W4: YES | X4: YES | Y4: YES | Z4: YES | AA4: YES
A5: =A4+1 -> 3 | B5: Chien Y | AA5: YES
A6: =A5+1 -> 4 | B6: Corban | C6: Stevens | D6: Male | E6: Regina Stevens | F6: ar_stevens@icloud.com | G6: 0348 055 054 | H6: Trailblazers | V6: YES | X6: YES | Y6: YES | Z6: YES | AA6: YES
A7: =A6+1 -> 5 | B7: Daniella | C7: Udombat | D7: Female | E7: Inyene Udombat | F7: inyeneudombat@gmail.com | G7: 0364 473 250 | H7: Trailblazers | I7: YES | L7: YES | N7: YES | Q7: YES | S7: YES | U7: YES | V7: YES
A8: =A7+1 -> 6 | B8: Dante | H8: Trailblazers | X8: YES | AA8: YES
A9: =A8+1 -> 7 | B9: Edric (Eggsy) | C9: Jugunta | D9: Male | E9: Vinoth Jugunta | F9: pinkn112@gmail.com | G9: 0916 226 559 | H9: Trailblazers | I9: YES | J9: YES | K9: YES | L9: YES | M9: YES | AA9: YES
A10: =A9+1 -> 8 | B10: Gabriel | C10: Pham | D10: Male | E10: Ngoc Cuong Joseph Pham | F10: joseph.pnc@gmail.com | G10: 0984 317 851 | H10: Trailblazers | I10: YES
A11: =A10+1 -> 9 | B11: Hannah | C11: Garcia | H11: Trailblazers | O11: YES
A12: =A11+1 -> 10 | B12: Hayu | H12: Trailblazers | T12: YES | U12: YES
A13: =A12+1 -> 11 | B13: Isaac | C13: Bennett | D13: Male | E13: Huong Bennett | F13: huonghd85@gmail.com | G13: 0383 231 380 | H13: Trailblazers | Q13: YES | U13: YES
A14: =A13+1 -> 12 | B14: Jaja | C14: Loyola | D14: Female | E14: Marife Loyola | F14: mafeployola79@gmail.com | H14: Trailblazers | W14: YES | X14: YES | Y14: YES | Z14: YES | AA14: YES
A15: =A14+1 -> 13 | B15: Joshua | C15: Patterson | D15: Male | E15: Martin Patterson | F15: martinp1987@live.co.uk | G15: 781 591 6960 | H15: Trailblazers | I15: YES | K15: YES
A16: =A15+1 -> 14 | B16: Josiah | C16: Tran | D16: Male | E16: Ashley Tran | F16: vunashley@gmail.com | G16: 0398 954 451 | H16: Trailblazers | W16: YES | X16: YES | Y16: YES | Z16: YES | AA16: YES
